2025-07-11 11:39:40,251 - INFO - 启动微信公众号文章爬取 MCP 服务器...
2025-07-11 11:39:50,053 - ERROR - 服务器运行失败: unhandled errors in a TaskGroup (1 sub-exception)
2025-07-11 11:39:50,058 - ERROR - 详细错误信息:   + Exception Group Traceback (most recent call last):
  |   File "/Volumes/extend/github/python-wechat-mcp/weixin_server.py", line 327, in <module>
  |     mcp.run(transport='stdio')
  |     ~~~~~~~^^^^^^^^^^^^^^^^^^^
  |   File "/Volumes/extend/github/python-wechat-mcp/venv/lib/python3.13/site-packages/mcp/server/fastmcp/server.py", line 226, in run
  |     anyio.run(self.run_stdio_async)
  |     ~~~~~~~~~^^^^^^^^^^^^^^^^^^^^^^
  |   File "/Volumes/extend/github/python-wechat-mcp/venv/lib/python3.13/site-packages/anyio/_core/_eventloop.py", line 74, in run
  |     return async_backend.run(func, args, {}, backend_options)
  |            ~~~~~~~~~~~~~~~~~^^^^^^^^^^^^^^^^^^^^^^^^^^^^^^^^^
  |   File "/Volumes/extend/github/python-wechat-mcp/venv/lib/python3.13/site-packages/anyio/_backends/_asyncio.py", line 2310, in run
  |     return runner.run(wrapper())
  |            ~~~~~~~~~~^^^^^^^^^^^
  |   File "/opt/homebrew/Cellar/python@3.13/3.13.5/Frameworks/Python.framework/Versions/3.13/lib/python3.13/asyncio/runners.py", line 118, in run
  |     return self._loop.run_until_complete(task)
  |            ~~~~~~~~~~~~~~~~~~~~~~~~~~~~~^^^^^^
  |   File "/opt/homebrew/Cellar/python@3.13/3.13.5/Frameworks/Python.framework/Versions/3.13/lib/python3.13/asyncio/base_events.py", line 725, in run_until_complete
  |     return future.result()
  |            ~~~~~~~~~~~~~^^
  |   File "/Volumes/extend/github/python-wechat-mcp/venv/lib/python3.13/site-packages/anyio/_backends/_asyncio.py", line 2298, in wrapper
  |     return await func(*args)
  |            ^^^^^^^^^^^^^^^^^
  |   File "/Volumes/extend/github/python-wechat-mcp/venv/lib/python3.13/site-packages/mcp/server/fastmcp/server.py", line 632, in run_stdio_async
  |     async with stdio_server() as (read_stream, write_stream):
  |                ~~~~~~~~~~~~^^
  |   File "/opt/homebrew/Cellar/python@3.13/3.13.5/Frameworks/Python.framework/Versions/3.13/lib/python3.13/contextlib.py", line 221, in __aexit__
  |     await anext(self.gen)
  |   File "/Volumes/extend/github/python-wechat-mcp/venv/lib/python3.13/site-packages/mcp/server/stdio.py", line 85, in stdio_server
  |     async with anyio.create_task_group() as tg:
  |                ~~~~~~~~~~~~~~~~~~~~~~~^^
  |   File "/Volumes/extend/github/python-wechat-mcp/venv/lib/python3.13/site-packages/anyio/_backends/_asyncio.py", line 772, in __aexit__
  |     raise BaseExceptionGroup(
  |         "unhandled errors in a TaskGroup", self._exceptions
  |     ) from None
  | ExceptionGroup: unhandled errors in a TaskGroup (1 sub-exception)
  +-+---------------- 1 ----------------
    | Traceback (most recent call last):
    |   File "/Volumes/extend/github/python-wechat-mcp/venv/lib/python3.13/site-packages/mcp/server/stdio.py", line 63, in stdin_reader
    |     async for line in stdin:
    |     ...<7 lines>...
    |         await read_stream_writer.send(session_message)
    |   File "/Volumes/extend/github/python-wechat-mcp/venv/lib/python3.13/site-packages/anyio/_core/_fileio.py", line 83, in __aiter__
    |     line = await self.readline()
    |            ^^^^^^^^^^^^^^^^^^^^^
    |   File "/Volumes/extend/github/python-wechat-mcp/venv/lib/python3.13/site-packages/anyio/_core/_fileio.py", line 99, in readline
    |     return await to_thread.run_sync(self._fp.readline)
    |            ^^^^^^^^^^^^^^^^^^^^^^^^^^^^^^^^^^^^^^^^^^^
    |   File "/Volumes/extend/github/python-wechat-mcp/venv/lib/python3.13/site-packages/anyio/to_thread.py", line 56, in run_sync
    |     return await get_async_backend().run_sync_in_worker_thread(
    |            ^^^^^^^^^^^^^^^^^^^^^^^^^^^^^^^^^^^^^^^^^^^^^^^^^^^^
    |         func, args, abandon_on_cancel=abandon_on_cancel, limiter=limiter
    |         ^^^^^^^^^^^^^^^^^^^^^^^^^^^^^^^^^^^^^^^^^^^^^^^^^^^^^^^^^^^^^^^^
    |     )
    |     ^
    |   File "/Volumes/extend/github/python-wechat-mcp/venv/lib/python3.13/site-packages/anyio/_backends/_asyncio.py", line 2470, in run_sync_in_worker_thread
    |     return await future
    |            ^^^^^^^^^^^^
    |   File "/Volumes/extend/github/python-wechat-mcp/venv/lib/python3.13/site-packages/anyio/_backends/_asyncio.py", line 967, in run
    |     result = context.run(func, *args)
    | OSError: [Errno 5] Input/output error
    +------------------------------------

